<?xml version='1.0'?>
<sdf version='1.6'>
  <model name='adrien'>
    <pose>0 0 0 0 0 0</pose>
    <link name='base_link'>
      <velocity_decay>
        <linear>0.0</linear>
        <angular>0.0</angular>
      </velocity_decay>
      <inertial>
        <pose>0 0 0 0 0 0</pose>
        <mass>1.6</mass>
        <inertia>
          <ixx>0.029125</ixx>
          <ixy>0</ixy>
          <ixz>0</ixz>
          <iyy>0.029125</iyy>
          <iyz>0</iyz>
          <izz>0.055225</izz>
        </inertia>
      </inertial>
      <visual name='base_link_visual'>
        <geometry>
          <mesh>
            <uri>model://adrien/meshes/drone_assembly_wo_props.dae</uri>
          </mesh>
        </geometry>
      </visual>

      <collision name='front_left_leg_collision'>
        <pose>0.0989 0.1209 -0.047 0 0 0</pose>
        <geometry>
          <cylinder>
            <radius>0.005</radius>
            <length>0.09</length>
          </cylinder>
        </geometry>
        <surface>
          <contact>
            <ode>
              <max_vel>100.0</max_vel>
              <min_depth>0.001</min_depth>
            </ode>
          </contact>
          <friction>
            <ode>
              <mu>100000.0</mu>
              <mu2>100000.0</mu2>
            </ode>
          </friction>
        </surface>
      </collision>
      <collision name='front_right_leg_collision'>
        <pose>0.0989 -0.1209 -0.047 0 0 0</pose>
        <geometry>
          <cylinder>
            <radius>0.005</radius>
            <length>0.09</length>
          </cylinder>
        </geometry>
        <surface>
          <contact>
            <ode>
              <max_vel>100.0</max_vel>
              <min_depth>0.001</min_depth>
            </ode>
          </contact>
          <friction>
            <ode>
              <mu>100000.0</mu>
              <mu2>100000.0</mu2>
            </ode>
          </friction>
        </surface>
      </collision>
      <collision name='rear_left_leg_collision'>
        <pose>-0.0989 0.1209 -0.047 0 0 0</pose>
        <geometry>
          <cylinder>
            <radius>0.005</radius>
            <length>0.09</length>
          </cylinder>
        </geometry>
        <surface>
          <contact>
            <ode>
              <max_vel>100.0</max_vel>
              <min_depth>0.001</min_depth>
            </ode>
          </contact>
          <friction>
            <ode>
              <mu>100000.0</mu>
              <mu2>100000.0</mu2>
            </ode>
          </friction>
        </surface>
      </collision>
      <collision name='rear_right_leg_collision'>
        <pose>-0.0989 -0.1209 -0.047 0 0 0</pose>
        <geometry>
          <cylinder>
            <radius>0.005</radius>
            <length>0.09</length>
          </cylinder>
        </geometry>
        <surface>
          <contact>
            <ode>
              <max_vel>100.0</max_vel>
              <min_depth>0.001</min_depth>
            </ode>
          </contact>
          <friction>
            <ode>
              <mu>100000.0</mu>
              <mu2>100000.0</mu2>
            </ode>
          </friction>
        </surface>
      </collision>
    </link>

    <link name='/imu_link'>
      <pose>0 0 0.025 0 0 0</pose>
      <inertial>
        <pose>0 0 0 0 0 0</pose>
        <mass>0.015</mass>
        <inertia>
          <ixx>1e-05</ixx>
          <ixy>0</ixy>
          <ixz>0</ixz>
          <iyy>1e-05</iyy>
          <iyz>0</iyz>
          <izz>1e-05</izz>
        </inertia>
      </inertial>
    </link>
    <joint name='/imu_joint' type='revolute'>
      <child>/imu_link</child>
      <parent>base_link</parent>
      <axis>
        <xyz>1 0 0</xyz>
        <limit>
          <lower>0</lower>
          <upper>0</upper>
          <effort>0</effort>
          <velocity>0</velocity>
        </limit>
        <dynamics>
          <spring_reference>0</spring_reference>
          <spring_stiffness>0</spring_stiffness>
        </dynamics>
        <use_parent_model_frame>1</use_parent_model_frame>
      </axis>
    </joint>

    <link name='rotor_0'>
      <pose>0.0989 -0.1209 0.02 0 0 0</pose>
      <inertial>
        <pose>0 0 0 0 -0 0</pose>
        <mass>0.025</mass>
        <inertia>
          <ixx>9.75e-06</ixx>
          <ixy>0</ixy>
          <ixz>0</ixz>
          <iyy>0.000166704</iyy>
          <iyz>0</iyz>
          <izz>0.000167604</izz>
        </inertia>
      </inertial>
      <collision name='rotor_0_collision'>
        <pose>0 0 0 0 -0 0</pose>
        <geometry>
          <!-- d = 7 inch disk shape collision -->
          <cylinder>
            <length>0.005</length>
            <radius>0.0889</radius>
          </cylinder>
        </geometry>
        <surface>
          <contact>
            <ode />
          </contact>
          <friction>
            <ode />
          </friction>
        </surface>
      </collision>
      <visual name='rotor_0_visual'>
        <pose>0 0 0 0 -0 0</pose>
        <geometry>
          <mesh>
            <scale>1 1 1</scale>
            <uri>model://adrien/meshes/prop_ccw.dae</uri>
          </mesh>
        </geometry>
        <material>
          <script>
            <name>Gazebo/Blue</name>
            <uri>__default__</uri>
          </script>
        </material>
      </visual>
      <gravity>1</gravity>
      <velocity_decay />
      <self_collide>0</self_collide>
    </link>
    <joint name='rotor_0_joint' type='revolute'>
      <child>rotor_0</child>
      <parent>base_link</parent>
      <axis>
        <xyz>0 0 1</xyz>
        <limit>
          <lower>-1e+16</lower>
          <upper>1e+16</upper>
        </limit>
        <dynamics>
          <spring_reference>0</spring_reference>
          <spring_stiffness>0</spring_stiffness>
        </dynamics>
        <use_parent_model_frame>1</use_parent_model_frame>
      </axis>
      <sensor name="force_torque" type="force_torque">
        <update_rate>30</update_rate>
      </sensor>
    </joint>
    <link name="rotor_1">
      <pose>-0.0989 0.1209 0.02 0 0 0</pose>
      <inertial>
        <pose>0 0 0 0 -0 0</pose>
        <mass>0.025</mass>
        <inertia>
          <ixx>9.75e-06</ixx>
          <ixy>0</ixy>
          <ixz>0</ixz>
          <iyy>0.000166704</iyy>
          <iyz>0</iyz>
          <izz>0.000167604</izz>
        </inertia>
      </inertial>
      <collision name="rotor_1_collision">
        <pose>0 0 0 0 -0 0</pose>
        <geometry>
          <!-- d = 7 inch disk shape collision -->
          <cylinder>
            <length>0.005</length>
            <radius>0.0889</radius>
          </cylinder>
        </geometry>
        <surface>
          <contact>
            <ode />
          </contact>
          <friction>
            <ode />
          </friction>
        </surface>
      </collision>
      <visual name="rotor_1_visual">
        <pose>0 0 0 0 -0 0</pose>
        <geometry>
          <mesh>
            <scale>1 1 1</scale>
            <uri>model://adrien/meshes/prop_ccw.dae</uri>
          </mesh>
        </geometry>
        <material>
          <script>
            <name>Gazebo/Blue</name>
            <uri>__default__</uri>
          </script>
        </material>
      </visual>
      <gravity>1</gravity>
      <velocity_decay />
      <self_collide>0</self_collide>
    </link>
    <joint name="rotor_1_joint" type="revolute">
      <child>rotor_1</child>
      <parent>base_link</parent>
      <axis>
        <xyz>0 0 1</xyz>
        <limit>
          <lower>-1e+16</lower>
          <upper>1e+16</upper>
        </limit>
        <dynamics>
          <spring_reference>0</spring_reference>
          <spring_stiffness>0</spring_stiffness>
        </dynamics>
        <use_parent_model_frame>1</use_parent_model_frame>
      </axis>
      <sensor name="force_torque" type="force_torque">
        <update_rate>30</update_rate>
      </sensor>
    </joint>
    <link name="rotor_2">
      <pose>0.0989 0.1209 0.02 0 0 0</pose>
      <inertial>
        <pose>0 0 0 0 -0 0</pose>
        <mass>0.025</mass>
        <inertia>
          <ixx>9.75e-06</ixx>
          <ixy>0</ixy>
          <ixz>0</ixz>
          <iyy>0.000166704</iyy>
          <iyz>0</iyz>
          <izz>0.000167604</izz>
        </inertia>
      </inertial>
      <collision name="rotor_2_collision">
        <pose>0 0 0 0 -0 0</pose>
        <geometry>
          <!-- d = 7 inch disk shape collision -->
          <cylinder>
            <length>0.005</length>
            <radius>0.0889</radius>
          </cylinder>
        </geometry>
        <surface>
          <contact>
            <ode />
          </contact>
          <friction>
            <ode />
          </friction>
        </surface>
      </collision>
      <visual name="rotor_2_visual">
        <pose>0 0 0 0 -0 0</pose>
        <geometry>
          <mesh>
            <scale>1 1 1</scale>
            <uri>model://adrien/meshes/prop_cw.dae</uri>
          </mesh>
        </geometry>
        <material>
          <script>
            <name>Gazebo/Blue</name>
            <uri>__default__</uri>
          </script>
        </material>
      </visual>
      <gravity>1</gravity>
      <velocity_decay />
      <self_collide>0</self_collide>
    </link>
    <joint name="rotor_2_joint" type="revolute">
      <child>rotor_2</child>
      <parent>base_link</parent>
      <axis>
        <xyz>0 0 1</xyz>
        <limit>
          <lower>-1e+16</lower>
          <upper>1e+16</upper>
        </limit>
        <dynamics>
          <spring_reference>0</spring_reference>
          <spring_stiffness>0</spring_stiffness>
        </dynamics>
        <use_parent_model_frame>1</use_parent_model_frame>
      </axis>
      <sensor name="force_torque" type="force_torque">
        <update_rate>30</update_rate>
      </sensor>
    </joint>
    <link name="rotor_3">
      <pose>-0.0989 -0.1209 0.02 0 0 0</pose>
      <inertial>
        <pose>0 0 0 0 -0 0</pose>
        <mass>0.025</mass>
        <inertia>
          <ixx>9.75e-06</ixx>
          <ixy>0</ixy>
          <ixz>0</ixz>
          <iyy>0.000166704</iyy>
          <iyz>0</iyz>
          <izz>0.000167604</izz>
        </inertia>
      </inertial>
      <collision name="rotor_3_collision">
        <pose>0 0 0 0 -0 0</pose>
        <geometry>
          <!-- d = 7 inch disk shape collision -->
          <cylinder>
            <length>0.005</length>
            <radius>0.0889</radius>
          </cylinder>
        </geometry>
        <surface>
          <contact>
            <ode />
          </contact>
          <friction>
            <ode />
          </friction>
        </surface>
      </collision>
      <visual name="rotor_3_visual">
        <pose>0 0 0 0 -0 0</pose>
        <geometry>
          <mesh>
            <scale>1 1 1</scale>
            <uri>model://adrien/meshes/prop_cw.dae</uri>
          </mesh>
        </geometry>
        <material>
          <script>
            <name>Gazebo/Blue</name>
            <uri>__default__</uri>
          </script>
        </material>
      </visual>
      <gravity>1</gravity>
      <velocity_decay />
      <self_collide>0</self_collide>
    </link>
    <joint name="rotor_3_joint" type="revolute">
      <child>rotor_3</child>
      <parent>base_link</parent>
      <axis>
        <xyz>0 0 1</xyz>
        <limit>
          <lower>-1e+16</lower>
          <upper>1e+16</upper>
        </limit>
        <dynamics>
          <spring_reference>0</spring_reference>
          <spring_stiffness>0</spring_stiffness>
        </dynamics>
        <use_parent_model_frame>1</use_parent_model_frame>
      </axis>
      <sensor name="force_torque" type="force_torque">
        <update_rate>30</update_rate>
      </sensor>
    </joint>

    <!-- px4 plugins -->

    <plugin name='rosbag' filename='libgazebo_multirotor_base_plugin.so'>
      <robotNamespace />
      <linkName>base_link</linkName>
      <rotorVelocitySlowdownSim>20</rotorVelocitySlowdownSim>
    </plugin>

    <!-- motor model : T-MOTOR F90 KV1300 6S -->
    <!-- prop model  : HQProp 70403 -->

    <plugin name='front_right_motor_model' filename='libgazebo_motor_model.so'>
      <robotNamespace />
      <jointName>rotor_0_joint</jointName>
      <linkName>rotor_0</linkName>
      <turningDirection>ccw</turningDirection>
      <timeConstantUp>0.0125</timeConstantUp>
      <timeConstantDown>0.025</timeConstantDown>
      <maxRotVelocity>2054</maxRotVelocity>
      <motorConstant>5.35573e-06</motorConstant>
      <momentConstant>0.01</momentConstant>
      <commandSubTopic>/gazebo/command/motor_speed</commandSubTopic>
      <motorNumber>0</motorNumber>
      <rotorDragCoefficient>0.0000875</rotorDragCoefficient>
      <rollingMomentCoefficient>5e-07</rollingMomentCoefficient>
      <motorSpeedPubTopic>/motor_speed/0</motorSpeedPubTopic>
      <rotorVelocitySlowdownSim>20</rotorVelocitySlowdownSim>
    </plugin>
    <plugin name='back_left_motor_model' filename='libgazebo_motor_model.so'>
      <robotNamespace />
      <jointName>rotor_1_joint</jointName>
      <linkName>rotor_1</linkName>
      <turningDirection>ccw</turningDirection>
      <timeConstantUp>0.0125</timeConstantUp>
      <timeConstantDown>0.025</timeConstantDown>
      <maxRotVelocity>2054</maxRotVelocity>
      <motorConstant>5.35573e-06</motorConstant>
      <momentConstant>0.01</momentConstant>
      <commandSubTopic>/gazebo/command/motor_speed</commandSubTopic>
      <motorNumber>1</motorNumber>
      <rotorDragCoefficient>0.0000875</rotorDragCoefficient>
      <rollingMomentCoefficient>5e-07</rollingMomentCoefficient>
      <motorSpeedPubTopic>/motor_speed/1</motorSpeedPubTopic>
      <rotorVelocitySlowdownSim>20</rotorVelocitySlowdownSim>
    </plugin>
    <plugin name='front_left_motor_model' filename='libgazebo_motor_model.so'>
      <robotNamespace />
      <jointName>rotor_2_joint</jointName>
      <linkName>rotor_2</linkName>
      <turningDirection>cw</turningDirection>
      <timeConstantUp>0.0125</timeConstantUp>
      <timeConstantDown>0.025</timeConstantDown>
      <maxRotVelocity>2054</maxRotVelocity>
      <motorConstant>5.35573e-06</motorConstant>
      <momentConstant>0.01</momentConstant>
      <commandSubTopic>/gazebo/command/motor_speed</commandSubTopic>
      <motorNumber>2</motorNumber>
      <rotorDragCoefficient>0.0000875</rotorDragCoefficient>
      <rollingMomentCoefficient>5e-07</rollingMomentCoefficient>
      <motorSpeedPubTopic>/motor_speed/2</motorSpeedPubTopic>
      <rotorVelocitySlowdownSim>20</rotorVelocitySlowdownSim>
    </plugin>
    <plugin name='back_right_motor_model' filename='libgazebo_motor_model.so'>
      <robotNamespace />
      <jointName>rotor_3_joint</jointName>
      <linkName>rotor_3</linkName>
      <turningDirection>cw</turningDirection>
      <timeConstantUp>0.0125</timeConstantUp>
      <timeConstantDown>0.025</timeConstantDown>
      <maxRotVelocity>2054</maxRotVelocity>
      <motorConstant>5.35573e-06</motorConstant>
      <momentConstant>0.01</momentConstant>
      <commandSubTopic>/gazebo/command/motor_speed</commandSubTopic>
      <motorNumber>3</motorNumber>
      <rotorDragCoefficient>0.0000875</rotorDragCoefficient>
      <rollingMomentCoefficient>5e-07</rollingMomentCoefficient>
      <motorSpeedPubTopic>/motor_speed/3</motorSpeedPubTopic>
      <rotorVelocitySlowdownSim>20</rotorVelocitySlowdownSim>
    </plugin>
    <include>
      <uri>model://gps</uri>
      <pose>0.05 0 0.04 0 0 0</pose>
      <name>gps0</name>
    </include>
    <joint name='gps0_joint' type='fixed'>
      <child>gps0::link</child>
      <parent>base_link</parent>
    </joint>
    <plugin name='groundtruth_plugin' filename='libgazebo_groundtruth_plugin.so'>
      <robotNamespace />
    </plugin>
    <plugin name='magnetometer_plugin' filename='libgazebo_magnetometer_plugin.so'>
      <robotNamespace />
      <pubRate>100</pubRate>
      <noiseDensity>0.0004</noiseDensity>
      <randomWalk>6.4e-06</randomWalk>
      <biasCorrelationTime>600</biasCorrelationTime>
      <magTopic>/mag</magTopic>
    </plugin>
    <plugin name='barometer_plugin' filename='libgazebo_barometer_plugin.so'>
      <robotNamespace />
      <pubRate>50</pubRate>
      <baroTopic>/baro</baroTopic>
      <baroDriftPaPerSec>0</baroDriftPaPerSec>
    </plugin>
    <plugin name='mavlink_interface' filename='libgazebo_mavlink_interface.so'>
      <robotNamespace />
      <imuSubTopic>/imu</imuSubTopic>
      <magSubTopic>/mag</magSubTopic>
      <baroSubTopic>/baro</baroSubTopic>
      <mavlink_addr>INADDR_ANY</mavlink_addr>
      <mavlink_tcp_port>4560</mavlink_tcp_port>
      <mavlink_udp_port>14560</mavlink_udp_port>
      <serialEnabled>0</serialEnabled>
      <serialDevice>/dev/ttyACM0</serialDevice>
      <baudRate>921600</baudRate>
      <qgc_addr>INADDR_ANY</qgc_addr>
      <qgc_udp_port>14550</qgc_udp_port>
      <sdk_addr>INADDR_ANY</sdk_addr>
      <sdk_udp_port>14540</sdk_udp_port>
      <hil_mode>0</hil_mode>
      <hil_state_level>0</hil_state_level>
      <send_vision_estimation>0</send_vision_estimation>
      <send_odometry>1</send_odometry>
      <enable_lockstep>1</enable_lockstep>
      <use_tcp>1</use_tcp>
      <motorSpeedCommandPubTopic>/gazebo/command/motor_speed</motorSpeedCommandPubTopic>
      <control_channels>
        <channel name='rotor1'>
          <input_index>0</input_index>
          <input_offset>0</input_offset>
          <input_scaling>2000</input_scaling>
          <zero_position_disarmed>0</zero_position_disarmed>
          <zero_position_armed>100</zero_position_armed>
          <joint_control_type>velocity</joint_control_type>
        </channel>
        <channel name='rotor2'>
          <input_index>1</input_index>
          <input_offset>0</input_offset>
          <input_scaling>2000</input_scaling>
          <zero_position_disarmed>0</zero_position_disarmed>
          <zero_position_armed>100</zero_position_armed>
          <joint_control_type>velocity</joint_control_type>
        </channel>
        <channel name='rotor3'>
          <input_index>2</input_index>
          <input_offset>0</input_offset>
          <input_scaling>2000</input_scaling>
          <zero_position_disarmed>0</zero_position_disarmed>
          <zero_position_armed>100</zero_position_armed>
          <joint_control_type>velocity</joint_control_type>
        </channel>
        <channel name='rotor4'>
          <input_index>3</input_index>
          <input_offset>0</input_offset>
          <input_scaling>2000</input_scaling>
          <zero_position_disarmed>0</zero_position_disarmed>
          <zero_position_armed>100</zero_position_armed>
          <joint_control_type>velocity</joint_control_type>
        </channel>
      </control_channels>
    </plugin>
    <static>0</static>
    <plugin name='rotors_gazebo_imu_plugin' filename='libgazebo_imu_plugin.so'>
      <robotNamespace />
      <linkName>/imu_link</linkName>
      <imuTopic>/imu</imuTopic>
      <gyroscopeNoiseDensity>0.00018665</gyroscopeNoiseDensity>
      <gyroscopeRandomWalk>3.8785e-05</gyroscopeRandomWalk>
      <gyroscopeBiasCorrelationTime>1000.0</gyroscopeBiasCorrelationTime>
      <gyroscopeTurnOnBiasSigma>0.0087</gyroscopeTurnOnBiasSigma>
      <accelerometerNoiseDensity>0.00186</accelerometerNoiseDensity>
      <accelerometerRandomWalk>0.006</accelerometerRandomWalk>
      <accelerometerBiasCorrelationTime>300.0</accelerometerBiasCorrelationTime>
      <accelerometerTurnOnBiasSigma>0.196</accelerometerTurnOnBiasSigma>
    </plugin>

    <!-- rotor status tracker -->
    <plugin name="rotor_0_joint_state_tracker" filename="libgazebo_ros_p3d.so">
      <alwaysOn>true</alwaysOn>
      <frameName>base_link</frameName>
      <bodyName>rotor_0</bodyName>
      <topicName>trackers/rotor_0/joint_state</topicName>
      <updateRate>60</updateRate>
    </plugin>
    <plugin name="rotor_0_wrench_tracker" filename="libgazebo_ros_ft_sensor.so">
      <updateRate>60</updateRate>
      <topicName>trackers/rotor_0/wrench</topicName>
      <gaussianNoise>0.0</gaussianNoise>
      <jointName>rotor_0_joint</jointName>
    </plugin>
    <plugin name="rotor_1_joint_state_tracker" filename="libgazebo_ros_p3d.so">
      <alwaysOn>true</alwaysOn>
      <frameName>base_link</frameName>
      <bodyName>rotor_1</bodyName>
      <topicName>trackers/rotor_1/joint_state</topicName>
      <updateRate>60</updateRate>
    </plugin>
    <plugin name="rotor_1_wrench_tracker" filename="libgazebo_ros_ft_sensor.so">
      <updateRate>60</updateRate>
      <topicName>trackers/rotor_1/wrench</topicName>
      <gaussianNoise>0.0</gaussianNoise>
      <jointName>rotor_1_joint</jointName>
    </plugin>
    <plugin name="rotor_2_joint_state_tracker" filename="libgazebo_ros_p3d.so">
      <alwaysOn>true</alwaysOn>
      <frameName>base_link</frameName>
      <bodyName>rotor_2</bodyName>
      <topicName>trackers/rotor_2/joint_state</topicName>
      <updateRate>60</updateRate>
    </plugin>
    <plugin name="rotor_2_wrench_tracker" filename="libgazebo_ros_ft_sensor.so">
      <updateRate>60</updateRate>
      <topicName>trackers/rotor_2/wrench</topicName>
      <gaussianNoise>0.0</gaussianNoise>
      <jointName>rotor_2_joint</jointName>
    </plugin>
    <plugin name="rotor_3_joint_state_tracker" filename="libgazebo_ros_p3d.so">
      <alwaysOn>true</alwaysOn>
      <frameName>base_link</frameName>
      <bodyName>rotor_3</bodyName>
      <topicName>trackers/rotor_3/joint_state</topicName>
      <updateRate>60</updateRate>
    </plugin>
    <plugin name="rotor_3_wrench_tracker" filename="libgazebo_ros_ft_sensor.so">
      <updateRate>60</updateRate>
      <topicName>trackers/rotor_3/wrench</topicName>
      <gaussianNoise>0.0</gaussianNoise>
      <jointName>rotor_3_joint</jointName>
    </plugin>

    <!-- body position/velocity tracker -->
    <plugin name="base_link_state_tracker" filename="libgazebo_ros_p3d.so">
      <alwaysOn>true</alwaysOn>
      <frameName>world</frameName>
      <bodyName>base_link</bodyName>
      <topicName>trackers/base_link/joint_state</topicName>
      <updateRate>60</updateRate>
    </plugin>

    <!-- realsense stereo camera-->
    <link name="realsense_link">
      <pose>0.096 0 -0.03 0 0 0</pose>
      <collision name="realsense_link_collision">
        <pose>0 0 0 -1.57 0 -1.57</pose>
        <geometry>
          <box>
            <size>0.02505 0.090 0.025</size>
          </box>
        </geometry>
      </collision>
      <inertial>
        <pose>0 0 0 0 0 0</pose>
        <inertia>
          <ixx>0.001</ixx>
          <ixy>0.000</ixy>
          <ixz>0.000</ixz>
          <iyy>0.001</iyy>
          <iyz>0.000</iyz>
          <izz>0.001</izz>
        </inertia>
        <mass>0.001</mass>
      </inertial>

      <sensor name="cameradepth" type="depth">
        <camera name="camera">
          <horizontal_fov>1.57</horizontal_fov>
          <image>
            <width>1280</width>
            <height>720</height>
          </image>
          <clip>
            <near>0.1</near>
            <far>100</far>
          </clip>
          <noise>
            <type>gaussian</type>
            <mean>0.0</mean>
            <stddev>0.100</stddev>
          </noise>
        </camera>
        <always_on>1</always_on>
        <update_rate>10</update_rate>
        <visualize>0</visualize>
      </sensor>
      <sensor name="cameracolor" type="camera">
        <camera name="camera">
          <horizontal_fov>1.57</horizontal_fov>
          <image>
            <width>1280</width>
            <height>720</height>
            <format>RGB_INT8</format>
          </image>
          <clip>
            <near>0.1</near>
            <far>100</far>
          </clip>
          <noise>
            <type>gaussian</type>
            <mean>0.0</mean>
            <stddev>0.007</stddev>
          </noise>
        </camera>
        <always_on>1</always_on>
        <update_rate>10</update_rate>
        <visualize>1</visualize>
      </sensor>
      <sensor name="cameraired1" type="camera">
        <camera name="camera">
          <horizontal_fov>1.57</horizontal_fov>
          <image>
            <width>320</width>
            <height>240</height>
            <format>L_INT8</format>
          </image>
          <clip>
            <near>0.1</near>
            <far>100</far>
          </clip>
          <noise>
            <type>gaussian</type>
            <mean>0.0</mean>
            <stddev>0.05</stddev>
          </noise>
        </camera>
        <always_on>1</always_on>
        <update_rate>1</update_rate>
        <visualize>0</visualize>
      </sensor>
      <sensor name="cameraired2" type="camera">
        <camera name="camera">
          <horizontal_fov>1.57</horizontal_fov>
          <image>
            <width>320</width>
            <height>240</height>
            <format>L_INT8</format>
          </image>
          <clip>
            <near>0.1</near>
            <far>100</far>
          </clip>
          <noise>
            <type>gaussian</type>
            <mean>0.0</mean>
            <stddev>0.05</stddev>
          </noise>
        </camera>
        <always_on>1</always_on>
        <update_rate>1</update_rate>
        <visualize>0</visualize>
      </sensor>
    </link>

    <joint name="realsense_joint" type="fixed">
      <parent>base_link</parent>
      <child>realsense_link</child>
      <pose>0 0 0 -1.57 0 -1.57</pose>
    </joint>

    <plugin name="camera" filename="librealsense_gazebo_plugin.so">
      <prefix>camera</prefix>
      <depthUpdateRate>10.0</depthUpdateRate>
      <colorUpdateRate>10.0</colorUpdateRate>
      <infraredUpdateRate>1.0</infraredUpdateRate>
      <depthTopicName>aligned_depth_to_color/image_raw</depthTopicName>
      <depthCameraInfoTopicName>depth/camera_info</depthCameraInfoTopicName>
      <colorTopicName>color/image_raw</colorTopicName>
      <colorCameraInfoTopicName>color/camera_info</colorCameraInfoTopicName>
      <infrared1TopicName>infra1/image_raw</infrared1TopicName>
      <infrared1CameraInfoTopicName>infra1/camera_info</infrared1CameraInfoTopicName>
      <infrared2TopicName>infra2/image_raw</infrared2TopicName>
      <infrared2CameraInfoTopicName>infra2/camera_info</infrared2CameraInfoTopicName>
      <colorOpticalframeName>camera_color_optical_frame</colorOpticalframeName>
      <depthOpticalframeName>camera_depth_optical_frame</depthOpticalframeName>
      <infrared1OpticalframeName>camera_left_ir_optical_frame</infrared1OpticalframeName>
      <infrared2OpticalframeName>camera_right_ir_optical_frame</infrared2OpticalframeName>
      <rangeMinDepth>0.2</rangeMinDepth>
      <rangeMaxDepth>10.0</rangeMaxDepth>
      <pointCloud>true</pointCloud>
      <pointCloudTopicName>depth/color/points</pointCloudTopicName>
      <pointCloudCutoff>0.25</pointCloudCutoff>
      <pointCloudCutoffMax>9.0</pointCloudCutoffMax>
    </plugin>

    <!-- optical flow sensors -->

    <link name="optical_flow_bottom_link">
      <pose>0.10783 -0.00735 -0.047658 -1.570796 1.570796 0</pose>

      <inertial>
        <mass>0.001</mass>
        <inertia>
          <ixx>1e-6</ixx>
          <iyy>1e-6</iyy>
          <izz>1e-6</izz>
        </inertia>
      </inertial>

      <light type="spot" name="point_light">
        <pose>0 0 0 0 0 0</pose>
        <diffuse>1 1 1 1</diffuse>
        <specular>.1 .1 .1 1</specular>
        <attenuation>
          <range>6</range>
          <linear>0.2</linear>
          <constant>0.8</constant>
          <quadratic>0.01</quadratic>
        </attenuation>
        <direction>1 0 0</direction>
        <spot>
          <inner_angle>1.0</inner_angle>
          <outer_angle>1.3</outer_angle>
          <falloff>1.0</falloff>
        </spot>
        <cast_shadows>true</cast_shadows>
      </light>

      <sensor name="optical_flow_bottom_camera" type="camera">
        <always_on>true</always_on>
        <update_rate>120</update_rate>
        <visualize>false</visualize>
        <topic>/optical_flow_bottom_camera</topic>
        <camera>
          <horizontal_fov>0.53</horizontal_fov>
          <lens>
            <type>gnomonical</type>
            <scale_to_hfov>false</scale_to_hfov>
          </lens>
          <image>
            <width>64</width>
            <height>64</height>
            <format>L8</format>
          </image>
          <clip>
            <near>0.08</near>
            <far>40</far>
          </clip>
          <noise>
            <type>gaussian</type>
            <mean>0.0</mean>
            <stddev>0.001</stddev>
          </noise>
        </camera>
        <plugin name="opticalflow_bottom_plugin" filename="libgazebo_ros_optical_flow.so">
          <robotNamespace></robotNamespace>
          <cameraName>optical_flow_bottom_camera</cameraName>
          <alwaysOn>true</alwaysOn>
          <outputRate>0</outputRate>
          <flowFeatureThreshold>30</flowFeatureThreshold>
          <flowValueThreshold>3000</flowValueThreshold>
          <topicName>optical_flow_bottom</topicName>
          <deltaTopicName>optical_flow_delta_bottom</deltaTopicName>
        </plugin>
      </sensor>
    </link>

    <joint name="optical_flow_bottom_joint" type="revolute">
      <parent>base_link</parent>
      <child>optical_flow_bottom_link</child>
      <axis>
        <xyz>0 0 1</xyz>
        <limit>
          <upper>0</upper>
          <lower>0</lower>
        </limit>
      </axis>
    </joint>

    <link name="optical_flow_left_link">
      <pose>-0.0077 0.048 -0.0672 0 0 1.570796</pose>

      <inertial>
        <mass>0.001</mass>
        <inertia>
          <ixx>1e-6</ixx>
          <iyy>1e-6</iyy>
          <izz>1e-6</izz>
        </inertia>
      </inertial>

      <light type="spot" name="point_light">
        <pose>0 0 0 0 0 0</pose>
        <diffuse>1 1 1 1</diffuse>
        <specular>.1 .1 .1 1</specular>
        <attenuation>
          <range>6</range>
          <linear>0.2</linear>
          <constant>0.8</constant>
          <quadratic>0.01</quadratic>
        </attenuation>
        <direction>1 0 0</direction>
        <spot>
          <inner_angle>1.0</inner_angle>
          <outer_angle>1.3</outer_angle>
          <falloff>1.0</falloff>
        </spot>
        <cast_shadows>true</cast_shadows>
      </light>

      <sensor name="optical_flow_left_camera" type="camera">
        <always_on>true</always_on>
        <update_rate>120</update_rate>
        <visualize>true</visualize>
        <topic>/optical_flow_left_camera</topic>
        <camera>
          <horizontal_fov>0.53</horizontal_fov>
          <lens>
            <type>gnomonical</type>
            <scale_to_hfov>false</scale_to_hfov>
          </lens>
          <image>
            <width>64</width>
            <height>64</height>
            <format>L8</format>
          </image>
          <clip>
            <near>0.08</near>
            <far>40</far>
          </clip>
          <noise>
            <type>gaussian</type>
            <mean>0.0</mean>
            <stddev>0.001</stddev>
          </noise>
        </camera>
        <plugin name="opticalflow_left_plugin" filename="libgazebo_ros_optical_flow.so">
          <robotNamespace></robotNamespace>
          <cameraName>optical_flow_left_camera</cameraName>
          <alwaysOn>true</alwaysOn>
          <outputRate>0</outputRate>
          <flowFeatureThreshold>30</flowFeatureThreshold>
          <flowValueThreshold>3000</flowValueThreshold>
          <topicName>optical_flow_left</topicName>
          <deltaTopicName>optical_flow_delta_left</deltaTopicName>
        </plugin>
      </sensor>
    </link>

    <joint name="optical_flow_left_joint" type="revolute">
      <parent>base_link</parent>
      <child>optical_flow_left_link</child>
      <axis>
        <xyz>0 0 1</xyz>
        <limit>
          <upper>0</upper>
          <lower>0</lower>
        </limit>
      </axis>
    </joint>

    <link name="optical_flow_right_link">
      <pose>-0.0077 -0.048 -0.0672 0 0 -1.570796</pose>

      <inertial>
        <mass>0.001</mass>
        <inertia>
          <ixx>1e-6</ixx>
          <iyy>1e-6</iyy>
          <izz>1e-6</izz>
        </inertia>
      </inertial>

      <light type="spot" name="point_light">
        <pose>0 0 0 0 0 0</pose>
        <diffuse>1 1 1 1</diffuse>
        <specular>.1 .1 .1 1</specular>
        <attenuation>
          <range>6</range>
          <linear>0.2</linear>
          <constant>0.8</constant>
          <quadratic>0.01</quadratic>
        </attenuation>
        <direction>1 0 0</direction>
        <spot>
          <inner_angle>1.0</inner_angle>
          <outer_angle>1.3</outer_angle>
          <falloff>1.0</falloff>
        </spot>
        <cast_shadows>true</cast_shadows>
      </light>

      <sensor name="optical_flow_right_camera" type="camera">
        <always_on>true</always_on>
        <update_rate>120</update_rate>
        <visualize>true</visualize>
        <topic>/optical_flow_right_camera</topic>
        <camera>
          <horizontal_fov>0.53</horizontal_fov>
          <lens>
            <type>gnomonical</type>
            <scale_to_hfov>false</scale_to_hfov>
          </lens>
          <image>
            <width>64</width>
            <height>64</height>
            <format>L8</format>
          </image>
          <clip>
            <near>0.08</near>
            <far>40</far>
          </clip>
          <noise>
            <type>gaussian</type>
            <mean>0.0</mean>
            <stddev>0.001</stddev>
          </noise>
        </camera>
        <plugin name="opticalflow_right_plugin" filename="libgazebo_ros_optical_flow.so">
          <robotNamespace></robotNamespace>
          <cameraName>optical_flow_right_camera</cameraName>
          <alwaysOn>true</alwaysOn>
          <outputRate>0</outputRate>
          <flowFeatureThreshold>30</flowFeatureThreshold>
          <flowValueThreshold>3000</flowValueThreshold>
          <topicName>optical_flow_right</topicName>
          <deltaTopicName>optical_flow_delta_right</deltaTopicName>
        </plugin>
      </sensor>
    </link>

    <joint name="optical_flow_right_joint" type="revolute">
      <parent>base_link</parent>
      <child>optical_flow_right_link</child>
      <axis>
        <xyz>0 0 1</xyz>
        <limit>
          <upper>0</upper>
          <lower>0</lower>
        </limit>
      </axis>
    </joint>

    <!-- multi zone lidar -->
    <link name="multi_zone_lidar_left_link">
      <pose>0.0075 0.0465 -0.0665 -1.570796 0 1.570796</pose>

      <inertial>
        <mass>0.001</mass>
        <inertia>
          <ixx>1e-6</ixx>
          <iyy>1e-6</iyy>
          <izz>1e-6</izz>
        </inertia>
      </inertial>

      <sensor name="multi_zone_lidar_left" type="ray">
        <always_on>true</always_on>
        <update_rate>15</update_rate>
        <visualize>true</visualize>
        <ray>
          <scan>
            <horizontal>
              <samples>8</samples>
              <resolution>1</resolution>
              <min_angle>-0.343612</min_angle>
              <max_angle>0.343612</max_angle>
            </horizontal>
            <vertical>
              <samples>8</samples>
              <resolution>1</resolution>
              <min_angle>-0.343612</min_angle>
              <max_angle> 0.343612</max_angle>
            </vertical>
          </scan>
          <range>
            <min>0.09</min>
            <max>3.0</max>
            <resolution>0.001</resolution>
          </range>
          <noise>
            <type>gaussian</type>
            <mean>0.0</mean>
            <stddev>0.0015</stddev>
          </noise>
        </ray>
        <plugin name="multi_zone_lidar_left_plugin" filename="libgazebo_ros_block_laser.so">
          <topicName>multi_zone_lidar_left/scan</topicName>
          <frameName>multi_zone_lidar_left_link</frameName>
          <min_range>0.09</min_range>
          <max_range>3.0</max_range>
          <updateRate>15</updateRate>
          <gaussianNoise>0.0015</gaussianNoise>
        </plugin>
      </sensor>
    </link>
    <joint name="multi_zone_lidar_left_joint" type="revolute">
      <parent>base_link</parent>
      <child>multi_zone_lidar_left_link</child>
      <axis>
        <xyz>0 0 1</xyz>
        <limit>
          <upper>0</upper>
          <lower>0</lower>
        </limit>
      </axis>
    </joint>
    <link name="multi_zone_lidar_right_link">
      <pose>0.0075 -0.0465 -0.0665 1.570796 0 -1.570796</pose>

      <inertial>
        <mass>0.001</mass>
        <inertia>
          <ixx>1e-6</ixx>
          <iyy>1e-6</iyy>
          <izz>1e-6</izz>
        </inertia>
      </inertial>

      <sensor name="multi_zone_lidar_right" type="ray">
        <always_on>true</always_on>
        <update_rate>15</update_rate>
        <visualize>true</visualize>
        <ray>
          <scan>
            <horizontal>
              <samples>8</samples>
              <resolution>1</resolution>
              <min_angle>-0.343612</min_angle>
              <max_angle>0.343612</max_angle>
            </horizontal>
            <vertical>
              <samples>8</samples>
              <resolution>1</resolution>
              <min_angle>-0.343612</min_angle>
              <max_angle> 0.343612</max_angle>
            </vertical>
          </scan>
          <range>
            <min>0.09</min>
            <max>3.0</max>
            <resolution>0.001</resolution>
          </range>
          <noise>
            <type>gaussian</type>
            <mean>0.0</mean>
            <stddev>0.0015</stddev>
          </noise>
        </ray>
        <plugin name="multi_zone_lidar_right_plugin" filename="libgazebo_ros_block_laser.so">
          <topicName>multi_zone_lidar_right/scan</topicName>
          <frameName>multi_zone_lidar_right_link</frameName>
          <min_range>0.09</min_range>
          <max_range>3.0</max_range>
          <updateRate>15</updateRate>
          <gaussianNoise>0.0015</gaussianNoise>
        </plugin>
      </sensor>
    </link>
    <joint name="multi_zone_lidar_right_joint" type="revolute">
      <parent>base_link</parent>
      <child>multi_zone_lidar_right_link</child>
      <axis>
        <xyz>0 0 1</xyz>
        <limit>
          <upper>0</upper>
          <lower>0</lower>
        </limit>
      </axis>
    </joint>

    <link name="multi_zone_lidar_front_left_link">
      <pose>0.112103 0.152774 -0.024 0 0 1.17809725</pose>

      <inertial>
        <mass>0.001</mass>
        <inertia>
          <ixx>1e-6</ixx>
          <iyy>1e-6</iyy>
          <izz>1e-6</izz>
        </inertia>
      </inertial>

      <sensor name="multi_zone_lidar_front_left" type="ray">
        <always_on>true</always_on>
        <update_rate>15</update_rate>
        <visualize>true</visualize>
        <ray>
          <scan>
            <horizontal>
              <samples>8</samples>
              <resolution>1</resolution>
              <min_angle>-0.343612</min_angle>
              <max_angle>0.343612</max_angle>
            </horizontal>
            <vertical>
              <samples>8</samples>
              <resolution>1</resolution>
              <min_angle>-0.343612</min_angle>
              <max_angle> 0.343612</max_angle>
            </vertical>
          </scan>
          <range>
            <min>0.09</min>
            <max>3.0</max>
            <resolution>0.001</resolution>
          </range>
          <noise>
            <type>gaussian</type>
            <mean>0.0</mean>
            <stddev>0.0015</stddev>
          </noise>
        </ray>
        <plugin name="multi_zone_lidar_front_left_plugin"
          filename="libgazebo_ros_block_laser.so">
          <topicName>multi_zone_lidar_front_left/scan</topicName>
          <frameName>multi_zone_lidar_front_left_link</frameName>
          <min_range>0.09</min_range>
          <max_range>3.0</max_range>
          <updateRate>15</updateRate>
          <gaussianNoise>0.0015</gaussianNoise>
        </plugin>
      </sensor>
    </link>
    <joint name="multi_zone_lidar_front_left_joint" type="revolute">
      <parent>base_link</parent>
      <child>multi_zone_lidar_front_left_link</child>
      <axis>
        <xyz>0 0 1</xyz>
        <limit>
          <upper>0</upper>
          <lower>0</lower>
        </limit>
      </axis>
    </joint>

    <link name="multi_zone_lidar_front_right_link">
      <pose>0.112103 -0.152774 -0.024 0 0 -1.17809725</pose>

      <inertial>
        <mass>0.001</mass>
        <inertia>
          <ixx>1e-6</ixx>
          <iyy>1e-6</iyy>
          <izz>1e-6</izz>
        </inertia>
      </inertial>

      <sensor name="multi_zone_lidar_front_right" type="ray">
        <always_on>true</always_on>
        <update_rate>15</update_rate>
        <visualize>true</visualize>
        <ray>
          <scan>
            <horizontal>
              <samples>8</samples>
              <resolution>1</resolution>
              <min_angle>-0.343612</min_angle>
              <max_angle>0.343612</max_angle>
            </horizontal>
            <vertical>
              <samples>8</samples>
              <resolution>1</resolution>
              <min_angle>-0.343612</min_angle>
              <max_angle> 0.343612</max_angle>
            </vertical>
          </scan>
          <range>
            <min>0.09</min>
            <max>3.0</max>
            <resolution>0.001</resolution>
          </range>
          <noise>
            <type>gaussian</type>
            <mean>0.0</mean>
            <stddev>0.0015</stddev>
          </noise>
        </ray>
        <plugin name="multi_zone_lidar_front_right_plugin"
          filename="libgazebo_ros_block_laser.so">
          <topicName>multi_zone_lidar_front_right/scan</topicName>
          <frameName>multi_zone_lidar_front_right_link</frameName>
          <min_range>0.09</min_range>
          <max_range>3.0</max_range>
          <updateRate>15</updateRate>
          <gaussianNoise>0.0015</gaussianNoise>
        </plugin>
      </sensor>
    </link>
    <joint name="multi_zone_lidar_front_right_joint" type="revolute">
      <parent>base_link</parent>
      <child>multi_zone_lidar_front_right_link</child>
      <axis>
        <xyz>0 0 1</xyz>
        <limit>
          <upper>0</upper>
          <lower>0</lower>
        </limit>
      </axis>
    </joint>

    <link name="multi_zone_lidar_rear_left_link">
      <pose>-0.112103 0.152774 -0.024 0 0 1.9634954</pose>

      <inertial>
        <mass>0.001</mass>
        <inertia>
          <ixx>1e-6</ixx>
          <iyy>1e-6</iyy>
          <izz>1e-6</izz>
        </inertia>
      </inertial>

      <sensor name="multi_zone_lidar_rear_left" type="ray">
        <always_on>true</always_on>
        <update_rate>15</update_rate>
        <visualize>true</visualize>
        <ray>
          <scan>
            <horizontal>
              <samples>8</samples>
              <resolution>1</resolution>
              <min_angle>-0.343612</min_angle>
              <max_angle>0.343612</max_angle>
            </horizontal>
            <vertical>
              <samples>8</samples>
              <resolution>1</resolution>
              <min_angle>-0.343612</min_angle>
              <max_angle> 0.343612</max_angle>
            </vertical>
          </scan>
          <range>
            <min>0.09</min>
            <max>3.0</max>
            <resolution>0.001</resolution>
          </range>
          <noise>
            <type>gaussian</type>
            <mean>0.0</mean>
            <stddev>0.0015</stddev>
          </noise>
        </ray>
        <plugin name="multi_zone_lidar_rear_left_plugin"
          filename="libgazebo_ros_block_laser.so">
          <topicName>multi_zone_lidar_rear_left/scan</topicName>
          <frameName>multi_zone_lidar_rear_left_link</frameName>
          <min_range>0.09</min_range>
          <max_range>3.0</max_range>
          <updateRate>15</updateRate>
          <gaussianNoise>0.0015</gaussianNoise>
        </plugin>
      </sensor>
    </link>
    <joint name="multi_zone_lidar_rear_left_joint" type="revolute">
      <parent>base_link</parent>
      <child>multi_zone_lidar_rear_left_link</child>
      <axis>
        <xyz>0 0 1</xyz>
        <limit>
          <upper>0</upper>
          <lower>0</lower>
        </limit>
      </axis>
    </joint>


    <link name="multi_zone_lidar_rear_right_link">
      <pose>-0.112103 -0.152774 -0.024 0 0 -1.9634954</pose>

      <inertial>
        <mass>0.001</mass>
        <inertia>
          <ixx>1e-6</ixx>
          <iyy>1e-6</iyy>
          <izz>1e-6</izz>
        </inertia>
      </inertial>

      <sensor name="multi_zone_lidar_rear_right" type="ray">
        <always_on>true</always_on>
        <update_rate>15</update_rate>
        <visualize>true</visualize>
        <ray>
          <scan>
            <horizontal>
              <samples>8</samples>
              <resolution>1</resolution>
              <min_angle>-0.343612</min_angle>
              <max_angle>0.343612</max_angle>
            </horizontal>
            <vertical>
              <samples>8</samples>
              <resolution>1</resolution>
              <min_angle>-0.343612</min_angle>
              <max_angle> 0.343612</max_angle>
            </vertical>
          </scan>
          <range>
            <min>0.09</min>
            <max>3.0</max>
            <resolution>0.001</resolution>
          </range>
          <noise>
            <type>gaussian</type>
            <mean>0.0</mean>
            <stddev>0.0015</stddev>
          </noise>
        </ray>
        <plugin name="multi_zone_lidar_rear_right_plugin"
          filename="libgazebo_ros_block_laser.so">
          <topicName>multi_zone_lidar_rear_right/scan</topicName>
          <frameName>multi_zone_lidar_rear_right_link</frameName>
          <min_range>0.09</min_range>
          <max_range>3.0</max_range>
          <updateRate>15</updateRate>
          <gaussianNoise>0.0015</gaussianNoise>
        </plugin>
      </sensor>
    </link>
    <joint name="multi_zone_lidar_rear_right_joint" type="revolute">
      <parent>base_link</parent>
      <child>multi_zone_lidar_rear_right_link</child>
      <axis>
        <xyz>0 0 1</xyz>
        <limit>
          <upper>0</upper>
          <lower>0</lower>
        </limit>
      </axis>
    </joint>

    <!-- rangefinders -->
    <link name="single_point_lidar_bottom_link">
      <pose>0.0875 0 -0.0555 0 1.570796 0</pose>

      <inertial>
        <mass>0.001</mass>
        <inertia>
          <ixx>1e-6</ixx>
          <iyy>1e-6</iyy>
          <izz>1e-6</izz>
        </inertia>
      </inertial>

      <sensor name="single_point_lidar_bottom" type="ray">
        <always_on>true</always_on>
        <update_rate>60</update_rate>
        <visualize>true</visualize>
        <ray>
          <scan>
            <horizontal>
              <samples>3</samples>
              <resolution>1</resolution>
              <min_angle>-0.0314159</min_angle>
              <max_angle>0.0314159</max_angle>
            </horizontal>
            <vertical>
              <samples>3</samples>
              <resolution>1</resolution>
              <min_angle>-0.0314159</min_angle>
              <max_angle>0.0314159</max_angle>
            </vertical>
          </scan>
          <range>
            <min>0.09</min>
            <max>3.0</max>
            <resolution>0.001</resolution>
          </range>
          <noise>
            <type>gaussian</type>
            <mean>0.0</mean>
            <stddev>0.0015</stddev>
          </noise>
        </ray>
        <plugin filename="libgazebo_ros_range.so" name="single_point_lidar_bottom_plugin">
          <robotNamespace></robotNamespace>
          <frameName>single_point_lidar_bottom_link</frameName>
          <topicName>single_point_lidar_bottom/range</topicName>
          <radiation>ultrasound</radiation>
          <fov>0.0628319</fov>
          <gaussianNoise>0.0015</gaussianNoise>
          <updateRate>60</updateRate>
        </plugin>
      </sensor>
    </link>
    <joint name="single_point_lidar_bottom_joint" type="revolute">
      <parent>base_link</parent>
      <child>single_point_lidar_bottom_link</child>
      <axis>
        <xyz>0 0 1</xyz>
        <limit>
          <upper>0</upper>
          <lower>0</lower>
        </limit>
      </axis>
    </joint>


    <link name="single_point_lidar_top_link">
      <pose>0.0875 0 0.026 0 -1.570796 0</pose>

      <inertial>
        <mass>0.001</mass>
        <inertia>
          <ixx>1e-6</ixx>
          <iyy>1e-6</iyy>
          <izz>1e-6</izz>
        </inertia>
      </inertial>

      <sensor name="single_point_lidar_top" type="ray">
        <always_on>true</always_on>
        <update_rate>60</update_rate>
        <visualize>true</visualize>
        <ray>
          <scan>
            <horizontal>
              <samples>3</samples>
              <resolution>1</resolution>
              <min_angle>-0.0314159</min_angle>
              <max_angle>0.0314159</max_angle>
            </horizontal>
            <vertical>
              <samples>3</samples>
              <resolution>1</resolution>
              <min_angle>-0.0314159</min_angle>
              <max_angle>0.0314159</max_angle>
            </vertical>
          </scan>
          <range>
            <min>0.09</min>
            <max>3.0</max>
            <resolution>0.001</resolution>
          </range>
          <noise>
            <type>gaussian</type>
            <mean>0.0</mean>
            <stddev>0.0015</stddev>
          </noise>
        </ray>
        <plugin filename="libgazebo_ros_range.so" name="single_point_lidar_top_plugin">
          <robotNamespace></robotNamespace>
          <frameName>single_point_lidar_top_link</frameName>
          <topicName>single_point_lidar_top/range</topicName>
          <radiation>ultrasound</radiation>
          <fov>0.0628319</fov>
          <gaussianNoise>0.0015</gaussianNoise>
          <updateRate>60</updateRate>
        </plugin>
      </sensor>
    </link>
    <joint name="single_point_lidar_top_joint" type="revolute">
      <parent>base_link</parent>
      <child>single_point_lidar_top_link</child>
      <axis>
        <xyz>0 0 1</xyz>
        <limit>
          <upper>0</upper>
          <lower>0</lower>
        </limit>
      </axis>
    </joint>

  </model>
</sdf>