<robot name="optical_flow_tester">
  <link name="base_link">
    <visual>
      <geometry>
        <box size="0.1 0.1 0.1" />
      </geometry>
      <material name="blue">
        <color rgba="0 0 1 1" />
      </material>
    </visual>
    <inertial>
      <mass value="1" />
      <inertia ixx="1" ixy="0" ixz="0" iyy="1" iyz="0" izz="1" />
    </inertial>
  </link>
  <link name="moving_link">
    <inertial>
      <mass value="1" />
      <inertia ixx="1" ixy="0" ixz="0" iyy="1" iyz="0" izz="1" />
    </inertial>
  </link>


  <joint name="static_joint" type="fixed">
    <parent link="world" />
    <child link="base_link" />
    <origin xyz="0 0 0" />
  </joint>
  <joint name="linear_joint" type="prismatic">
    <parent link="base_link" />
    <child link="optical_flow_link" />
    <origin xyz="0 0 0" />
    <axis xyz="0 1 0" />
    <limit effort="1000" lower="-1000000" upper="1000000" velocity="10" />
    <dynamics damping="0.7" friction="0.5" />
  </joint>

  <transmission name="linear_transmission">
    <type>transmission_interface/SimpleTransmission</type>
    <joint name="linear_joint">
      <hardwareInterface>hardware_interface/VelocityJointInterface</hardwareInterface>
    </joint>
    <actuator name="linear_motor">
      <hardwareInterface>hardware_interface/VelocityJointInterface</hardwareInterface>
    </actuator>
  </transmission>

</robot>